<?xml version="1.0" ?>
<!-- =================================================================================== -->
<!-- |    This document was autogenerated by xacro from Insertion_task.xacro           | -->
<!-- |    EDITING THIS FILE BY HAND IS NOT RECOMMENDED                                 | -->
<!-- =================================================================================== -->
<robot name="meca_standalone">
  <link name="base_link">
    <inertial>
      <origin rpy="0 0 0" xyz="0.0155742096146599 -0.045875694367467 0.0105063591743089"/>
      <mass value="0.701975266012108"/>
      <inertia ixx="0.00104999968536769" ixy="5.67451323688377E-08" ixz="-1.42053140449248E-06" iyy="0.000980207556335173" iyz="9.2922850615505E-05" izz="0.000826340578047908"/>
    </inertial>
    <visual>
      <origin rpy="0 0 0" xyz="0 0 0.0"/>
      <geometry>
        <mesh filename="base_link.STL"/>
      </geometry>
      <material name="">
        <color rgba="0.749019607843137 0.749019607843137 0.749019607843137 1"/>
      </material>
    </visual>
    <collision>
      <origin rpy="0 0 0" xyz="0 0 -0.02"/>
      <geometry>
        <cylinder length="0.04" radius="0.046"/>
      </geometry>
    </collision>
  </link>
  <link name="1_Link">
    <inertial>
      <origin rpy="0 0 0" xyz="0.0265829372353597 8.6108726099841E-07 0.0187309247071563"/>
      <mass value="0.00110681313497636"/>
      <inertia ixx="5.67802800750714E-09" ixy="-6.25280505779623E-13" ixz="2.07136842387982E-13" iyy="2.52736130363855E-08" iyz="3.97946980050579E-15" izz="2.52755748182286E-08"/>
    </inertial>
    <visual>
      <origin rpy="0 0 0" xyz="0 0 0"/>
      <geometry>
        <mesh filename="1_Link.STL"/>
      </geometry>
      <material name="">
        <color rgba="0.996078431372549 0.996078431372549 1 1"/>
      </material>
    </visual>
    <collision>
      <origin rpy="0 0 0" xyz="0 0 0"/>
      <geometry>
        <mesh filename="1_Link.STL"/>
      </geometry>
    </collision>
  </link>
  <joint name="1" type="revolute">
    <origin rpy="0 0 0" xyz="0.015543 0 -0.0046218"/>
    <parent link="base_link"/>
    <child link="1_Link"/>
    <axis xyz="0 0 1"/>
    <limit effort="10.0" lower="-3.0543" upper="3.0543" velocity="2.6180"/>
  </joint>
  <link name="2_Link">
    <inertial>
      <origin rpy="0 0 0" xyz="-0.011581 0.060433 0.025598"/>
      <mass value="0.0014997"/>
      <inertia ixx="4.1007E-08" ixy="2.5363E-14" ixz="-9.3123E-13" iyy="4.1011E-08" iyz="5.6892E-13" izz="4.3707E-09"/>
    </inertial>
    <visual>
      <origin rpy="0 0 0" xyz="0 0 0"/>
      <geometry>
        <mesh filename="2_Link.STL"/>
      </geometry>
      <material name="">
        <color rgba="0.74902 0.74902 0.74902 1"/>
      </material>
    </visual>
    <collision>
      <origin rpy="0 0 0" xyz="0 0 0"/>
      <geometry>
        <mesh filename="2_Link.STL"/>
      </geometry>
    </collision>
  </link>
  <joint name="2" type="revolute">
    <origin rpy="1.5708 0 1.5708" xyz="0 0 0.054"/>
    <parent link="1_Link"/>
    <child link="2_Link"/>
    <axis xyz="0 0 1"/>
    <limit effort="10.0" lower="-1.2217" upper="1.5708" velocity="2.6180"/>
  </joint>
  <link name="3_Link">
    <inertial>
      <origin rpy="0 0 0" xyz="0.00863474322368168 0.0130792726165944 0.000472372386690102"/>
      <mass value="0.369857547820667"/>
      <inertia ixx="0.000364951500986559" ixy="-6.79152264832734E-05" ixz="1.58659979825393E-06" iyy="0.000274459344759578" iyz="5.11361040289315E-06" izz="0.000449724288974004"/>
    </inertial>
    <visual>
      <origin rpy="0 0 0" xyz="0 0 0"/>
      <geometry>
        <mesh filename="3_Link.STL"/>
      </geometry>
      <material name="">
        <color rgba="0.749019607843137 0.749019607843137 0.749019607843137 1"/>
      </material>
    </visual>
    <collision>
      <origin rpy="0 0 0" xyz="0 0 0"/>
      <geometry>
        <mesh filename="3_Link.STL"/>
      </geometry>
    </collision>
  </link>
  <joint name="3" type="revolute">
    <origin rpy="0 0 0" xyz="0 0.135 0"/>
    <parent link="2_Link"/>
    <child link="3_Link"/>
    <axis xyz="0 0 1"/>
    <limit effort="10.0" lower="-2.3562" upper="1.2217" velocity="3.1416"/>
  </joint>
  <link name="4_Link">
    <inertial>
      <origin rpy="0 0 0" xyz="0.0268017397762453 3.8050478860796E-06 -0.0386580641288729"/>
      <mass value="5.4551423036358E-05"/>
      <inertia ixx="6.19250472386076E-11" ixy="-6.6627251186149E-15" ixz="3.36952177502071E-14" iyy="4.37621105880679E-10" iyz="5.44000654518049E-15" izz="4.37369303303002E-10"/>
    </inertial>
    <visual>
      <origin rpy="0 0 0" xyz="0 0 0"/>
      <geometry>
        <mesh filename="4_Link.STL"/>
      </geometry>
      <material name="">
        <color rgba="0.749019607843137 0.749019607843137 0.749019607843137 1"/>
      </material>
    </visual>
    <collision>
      <origin rpy="0 0 0" xyz="0 0 0"/>
      <geometry>
        <mesh filename="4_Link.STL"/>
      </geometry>
    </collision>
  </link>
  <joint name="4" type="revolute">
    <origin rpy="0 -1.5707963267949 0" xyz="0.0609985999996513 0.0380000639917407 0"/>
    <parent link="3_Link"/>
    <child link="4_Link"/>
    <axis xyz="0 0 1"/>
    <limit effort="10.0" lower="-2.9671" upper="2.9671" velocity="5.2360"/>
  </joint>
  <link name="5_Link">
    <inertial>
      <origin rpy="0 0 0" xyz="0.0205110139562634 2.54707156949197E-06 0.000506958591903185"/>
      <mass value="0.16436203042711"/>
      <inertia ixx="5.51456893060112E-05" ixy="8.28032699191258E-09" ixz="3.47996286604157E-06" iyy="0.000119500194381483" iyz="3.23812564504135E-09" izz="0.000115800437996737"/>
    </inertial>
    <visual>
      <origin rpy="0 0 0" xyz="0 0 0"/>
      <geometry>
        <mesh filename="5_Link.STL"/>
      </geometry>
      <material name="">
        <color rgba="0.749019607843137 0.749019607843137 0.749019607843137 1"/>
      </material>
    </visual>
    <collision>
      <origin rpy="0 0 0" xyz="0 0 0"/>
      <geometry>
        <mesh filename="5_Link.STL"/>
      </geometry>
    </collision>
  </link>
  <joint name="5" type="revolute">
    <origin rpy="0 1.5707963267949 0" xyz="0 0 -0.059"/>
    <parent link="4_Link"/>
    <child link="5_Link"/>
    <axis xyz="0 0 1"/>
    <limit effort="10.0" lower="-2.0071" upper="2.0071" velocity="5.2360"/>
  </joint>
  <link name="6_Link">
    <inertial>
      <origin rpy="0 0 0" xyz="-4.93381640404023E-09 -3.06476243447373E-06 -0.0051537334161223"/>
      <mass value="0.00318159115629491"/>
      <inertia ixx="1.12761623790943E-07" ixy="1.20821854288624E-13" ixz="-7.10637835162442E-14" iyy="1.10034690670702E-07" iyz="-4.50963801973578E-11" izz="1.63299994669183E-07"/>
    </inertial>
    <visual>
      <origin rpy="0 0 0" xyz="0 0 0"/>
      <geometry>
        <mesh filename="6_Link.STL"/>
      </geometry>
      <material name="">
        <color rgba="0.749019607843137 0.749019607843137 0.749019607843137 1"/>
      </material>
    </visual>
    <collision>
      <origin rpy="0 0 0" xyz="0 0 0"/>
      <geometry>
        <mesh filename="6_Link.STL"/>
      </geometry>
    </collision>
  </link>
  <joint name="6" type="revolute">
    <origin rpy="0.0 -1.5707963267949 0" xyz="0.059 0 0"/>
    <parent link="5_Link"/>
    <child link="6_Link"/>
    <axis xyz="0 0 1"/>
    <limit effort="10.0" lower="-6.2832" upper="6.2832" velocity="8.7266"/>
  </joint>
  <link name="world"/>
  <link name="Optical_breadboard4560">
    <visual>
      <origin rpy="1.5708 0 0" xyz="0 0 0"/>
      <geometry>
        <mesh filename="Optical_breadboard4560.STL" scale="0.001 0.001 0.001"/>
      </geometry>
      <material name="black">
        <color rgba="1 0.1 0.1 1"/>
      </material>
    </visual>
    <collision>
      <origin rpy="1.5708 0 0" xyz="0 0 0"/>
      <geometry>
        <mesh filename="Optical_breadboard4560.STL" scale="0.001 0.001 0.001"/>
      </geometry>
    </collision>
    <inertial>
      <mass value="0.2"/>
      <inertia ixx="0.001" ixy="0" ixz="0" iyy="0.001" iyz="0" izz="0.001"/>
    </inertial>
  </link>
  <joint name="Optical_breadboard4560" type="fixed">
    <parent link="world"/>
    <child link="Optical_breadboard4560"/>
    <origin rpy="0 0.0 0" xyz="-0.575 0.275 -0.1"/>
  </joint>
  <link name="Optical_tabel90120">
    <visual>
      <origin rpy="1.5708 0 0" xyz="0 0 0"/>
      <geometry>
        <mesh filename="Optical_tabel90120.STL" scale="0.001 0.001 0.001"/>
      </geometry>
      <material name="black">
        <color rgba="0.1 1 0.1 1"/>
      </material>
    </visual>
    <collision>
      <origin rpy="1.5708 0 0" xyz="0 0 0"/>
      <geometry>
        <mesh filename="Optical_tabel90120.STL" scale="0.001 0.001 0.001"/>
      </geometry>
    </collision>
    <inertial>
      <mass value="0.2"/>
      <inertia ixx="0.001" ixy="0" ixz="0" iyy="0.001" iyz="0" izz="0.001"/>
    </inertial>
  </link>
  <joint name="Optical_tabel90120" type="fixed">
    <parent link="Optical_breadboard4560"/>
    <child link="Optical_tabel90120"/>
    <origin rpy="0 0.0 0" xyz="-0.1 0.3 -0.13"/>
  </joint>
  <link name="Optical_plate">
    <visual>
      <origin rpy="1.5708 0 0" xyz="0 0 0"/>
      <geometry>
        <mesh filename="Optical_plate.STL" scale="0.001 0.001 0.001"/>
      </geometry>
      <material name="black">
        <color rgba="0.1 0.1 1 1"/>
      </material>
    </visual>
    <collision>
      <origin rpy="1.5708 0 0" xyz="0 0 0"/>
      <geometry>
        <mesh filename="Optical_plate.STL" scale="0.001 0.001 0.001"/>
      </geometry>
    </collision>
    <inertial>
      <mass value="0.2"/>
      <inertia ixx="0.001" ixy="0" ixz="0" iyy="0.001" iyz="0" izz="0.001"/>
    </inertial>
  </link>
  <joint name="Optical_plate" type="fixed">
    <parent link="Optical_breadboard4560"/>
    <child link="Optical_plate"/>
    <origin rpy="0 0.0 0" xyz="0.25 0 0.012"/>
  </joint>
  <link name="Trocar_plate">
    <inertial>
      <origin rpy="0 0 0" xyz="-0.010284 0.0012129 -0.024908"/>
      <mass value="0.030295"/>
      <inertia ixx="1.5333E-05" ixy="-4.7674E-22" ixz="-4.3837E-22" iyy="2.53E-05" iyz="-1.0486E-19" izz="4.0328E-05"/>
    </inertial>
    <visual>
      <origin rpy="0 0 0" xyz="0 0 0"/>
      <geometry>
        <mesh filename="Trocar_plate.STL"/>
      </geometry>
      <material name="">
        <color rgba="0.79216 0.81961 0.93333 1"/>
      </material>
    </visual>
    <collision>
      <origin rpy="0 0 0" xyz="0 0 0"/>
      <geometry>
        <mesh filename="Trocar_plate.STL"/>
      </geometry>
    </collision>
  </link>
  <joint name="Trocar_plate" type="fixed">
    <parent link="Optical_plate"/>
    <child link="Trocar_plate"/>
    <origin rpy="-1.5708 0.0 0.0" xyz="0.175 -0.06 0.1115"/>
  </joint>
  <link name="Trocar_cover">
    <inertial>
      <origin rpy="0 0 0" xyz="0 2.1684E-19 0.0031894"/>
      <mass value="0.051623"/>
      <inertia ixx="1.8441E-05" ixy="-6.6852E-38" ixz="-1.2085E-22" iyy="1.8441E-05" iyz="-1.0609E-38" izz="1.698E-05"/>
    </inertial>
    <visual>
      <origin rpy="0 0 0" xyz="0 0 0"/>
      <geometry>
        <mesh filename="Trocar_cover.STL"/>
      </geometry>
      <material name="">
        <color rgba="0.79216 0.81961 0.93333 1"/>
      </material>
    </visual>
    <collision>
      <origin rpy="0 0 0" xyz="0 0 0"/>
      <geometry>
        <mesh filename="Trocar_cover.STL"/>
      </geometry>
    </collision>
  </link>
  <joint name="Cover" type="revolute">
    <origin rpy="1.5708 0 0" xyz="-0.010284 0.006 0.0012129"/>
    <parent link="Trocar_plate"/>
    <child link="Trocar_cover"/>
    <axis xyz="0 0 1"/>
    <limit effort="0" lower="0" upper="0" velocity="0"/>
  </joint>
  <link name="Trocar_gripper">
    <inertial>
      <origin rpy="0 0 0" xyz="6.15921593302357E-08 0.00866204485646013 -8.45455101743803E-08"/>
      <mass value="0.000465099979144033"/>
      <inertia ixx="4.62973137158684E-08" ixy="-3.59081407708454E-13" ixz="-2.4218954980201E-18" iyy="4.54118427502853E-08" iyz="4.83325739784747E-13" izz="4.62973137174286E-08"/>
    </inertial>
    <visual>
      <origin rpy="0 0 0" xyz="0 0 0"/>
      <geometry>
        <mesh filename="Trocar_gripper.STL"/>
      </geometry>
      <material name="">
        <color rgba="0.792156862745098 0.819607843137255 0.933333333333333 1"/>
      </material>
    </visual>
    <collision>
      <origin rpy="0 0 0" xyz="0 0 0"/>
      <geometry>
        <mesh filename="Trocar_gripper.STL"/>
      </geometry>
    </collision>
  </link>
  <joint name="gripper" type="revolute">
    <origin rpy="1.5708 0 1.2559" xyz="0 0 0.005"/>
    <parent link="Trocar_cover"/>
    <child link="Trocar_gripper"/>
    <axis xyz="0 1 0"/>
    <limit effort="0" lower="0" upper="0" velocity="0"/>
  </joint>
  <link name="Eye_phantom">
    <inertial>
      <origin rpy="0 0 0" xyz="-0.012472312239797 -1.50679048680994E-05 -2.58139816005937E-05"/>
      <mass value="0.00166355152381348"/>
      <inertia ixx="1.67706142981398E-07" ixy="2.68078790732605E-10" ixz="-3.60065214288737E-10" iyy="1.50535164162634E-07" iyz="-2.37123987209198E-12" izz="1.51037126333486E-07"/>
    </inertial>
    <visual>
      <origin rpy="0 0 0" xyz="0 0 0"/>
      <geometry>
        <mesh filename="Eye_phantom.STL"/>
      </geometry>
      <material name="">
        <color rgba="1 1 1 1"/>
      </material>
    </visual>
    <collision>
      <origin rpy="0 0 0" xyz="0 0 0"/>
      <geometry>
        <mesh filename="Eye_phantom.STL"/>
      </geometry>
    </collision>
  </link>
  <joint name="Eye_phantom" type="revolute">
    <origin rpy="0.5 0.0 -1.5708" xyz="0 0 0"/>
    <parent link="Trocar_gripper"/>
    <child link="Eye_phantom"/>
    <axis xyz="1 0 0"/>
    <limit effort="0" lower="0" upper="0" velocity="0"/>
  </joint>
  <link name="Eye_trocar">
    <inertial>
      <origin rpy="0 0 0" xyz="0 3.03576608295941E-18 0.00446798310326308"/>
      <mass value="7.447930783498E-06"/>
      <inertia ixx="7.4544848639307E-12" ixy="-1.0097419586829E-28" ixz="-6.86624531904369E-27" iyy="7.4544848639307E-12" iyz="2.72630328844382E-27" izz="5.94805100211937E-12"/>
    </inertial>
    <visual>
      <origin rpy="0 0 0" xyz="0 0 0"/>
      <geometry>
        <mesh filename="Eye_trocar.STL"/>
      </geometry>
      <material name="">
        <color rgba="0.717647058823529 0.254901960784314 0 1"/>
      </material>
    </visual>
    <collision>
      <origin rpy="0 0 0" xyz="0 0 0"/>
      <geometry>
        <mesh filename="Eye_trocar.STL"/>
      </geometry>
    </collision>
  </link>
  <joint name="Eye_trocar" type="revolute">
    <origin rpy="0.2922 -0.64361 -0.45715" xyz="-0.018742 -3.9168E-05 0.0062012"/>
    <parent link="Eye_phantom"/>
    <child link="Eye_trocar"/>
    <axis xyz="0 0 1"/>
    <limit effort="0" lower="0" upper="0" velocity="0"/>
  </joint>
  <link name="260107_Total_assembly">
    <visual>
      <origin rpy="1.5708 0 0" xyz="0 0 0"/>
      <geometry>
        <mesh filename="260107_Total_assembly_simplified.STL" scale="0.001 0.001 0.001"/>
      </geometry>
      <material name="black">
        <color rgba="0.9 0.9 0.9 1"/>
      </material>
    </visual>
    <collision>
      <origin rpy="1.5708 0 0" xyz="0 0 0"/>
      <geometry>
        <mesh filename="260107_Total_assembly_simplified.STL" scale="0.001 0.001 0.001"/>
      </geometry>
    </collision>
    <inertial>
      <mass value="0.2"/>
      <inertia ixx="0.001" ixy="0" ixz="0" iyy="0.001" iyz="0" izz="0.001"/>
    </inertial>
  </link>
  <joint name="260107_Total_assembly" type="fixed">
    <parent link="6_Link"/>
    <child link="260107_Total_assembly"/>
    <origin rpy="1.5708 0.0 3.1416" xyz="0.105 -0.0325 0.0"/>
  </joint>
  <joint name="world_to_base" type="fixed">
    <parent link="world"/>
    <child link="base_link"/>
    <origin rpy="0 0 0" xyz="0 0 0"/>
  </joint>
</robot>
