<?xml version="1.0" encoding="utf-8"?>
<robot name="Meca500_urdf" xmlns:xacro="http://www.ros.org/wiki/xacro">
  <xacro:macro name="meca500_robot">
    <link name="base_link">
      <inertial>
        <origin xyz="0.0155742096146599 -0.045875694367467 0.0105063591743089" rpy="0 0 0" />
        <mass value="0.701975266012108" />
        <inertia ixx="0.00104999968536769" ixy="5.67451323688377E-08" ixz="-1.42053140449248E-06" iyy="0.000980207556335173" iyz="9.2922850615505E-05" izz="0.000826340578047908" />
      </inertial>
      <visual>
        <origin xyz="0 0 0.0" rpy="0 0 0" />
        <geometry>
          <mesh filename="base_link.STL" />
        </geometry>
        <material name="">
          <color rgba="0.749019607843137 0.749019607843137 0.749019607843137 1" />
        </material>
      </visual>
      <collision>
        <origin xyz="0 0 -0.02" rpy="0 0 0" />
        <geometry>
          <cylinder radius="0.046" length="0.04" />
        </geometry>
      </collision>
    </link>

    <link name="1_Link">
      <inertial>
        <origin xyz="0.0265829372353597 8.6108726099841E-07 0.0187309247071563" rpy="0 0 0" />
        <mass value="0.00110681313497636" />
        <inertia ixx="5.67802800750714E-09" ixy="-6.25280505779623E-13" ixz="2.07136842387982E-13" iyy="2.52736130363855E-08" iyz="3.97946980050579E-15" izz="2.52755748182286E-08" />
      </inertial>
      <visual>
        <origin xyz="0 0 0" rpy="0 0 0" />
        <geometry>
          <mesh filename="1_Link.STL" />
        </geometry>
        <material name="">
          <color rgba="0.996078431372549 0.996078431372549 1 1" />
        </material>
      </visual>
      <collision>
        <origin xyz="0 0 0" rpy="0 0 0" />
        <geometry>
          <mesh filename="1_Link.STL" />
        </geometry>
      </collision>
    </link>
    <joint name="1" type="revolute">
      <origin xyz="0.015543 0 -0.0046218" rpy="0 0 0" />
      <parent link="base_link" />
      <child link="1_Link" />
      <axis xyz="0 0 1" />
      <limit lower="-3.0543" upper="3.0543" effort="10.0" velocity="2.6180" />
    </joint>

    <link name="2_Link">
      <inertial>
        <origin xyz="-0.011581 0.060433 0.025598" rpy="0 0 0" />
        <mass value="0.0014997" />
        <inertia ixx="4.1007E-08" ixy="2.5363E-14" ixz="-9.3123E-13" iyy="4.1011E-08" iyz="5.6892E-13" izz="4.3707E-09" />
      </inertial>
      <visual>
        <origin xyz="0 0 0" rpy="0 0 0" />
        <geometry>
          <mesh filename="2_Link.STL" />
        </geometry>
        <material name="">
          <color rgba="0.74902 0.74902 0.74902 1" />
        </material>
      </visual>
      <collision>
        <origin xyz="0 0 0" rpy="0 0 0" />
        <geometry>
          <mesh filename="2_Link.STL" />
        </geometry>
      </collision>
    </link>
    <joint name="2" type="revolute">
      <origin xyz="0 0 0.054" rpy="1.5708 0 1.5708" />
      <parent link="1_Link" />
      <child link="2_Link" />
      <axis xyz="0 0 1" />
      <limit lower="-1.2217" upper="1.5708" effort="10.0" velocity="2.6180" />
    </joint>

    <link name="3_Link">
      <inertial>
        <origin xyz="0.00863474322368168 0.0130792726165944 0.000472372386690102" rpy="0 0 0" />
        <mass value="0.369857547820667" />
        <inertia ixx="0.000364951500986559" ixy="-6.79152264832734E-05" ixz="1.58659979825393E-06" iyy="0.000274459344759578" iyz="5.11361040289315E-06" izz="0.000449724288974004" />
      </inertial>
      <visual>
        <origin xyz="0 0 0" rpy="0 0 0" />
        <geometry>
          <mesh filename="3_Link.STL" />
        </geometry>
        <material name="">
          <color rgba="0.749019607843137 0.749019607843137 0.749019607843137 1" />
        </material>
      </visual>
      <collision>
        <origin xyz="0 0 0" rpy="0 0 0" />
        <geometry>
          <mesh filename="3_Link.STL" />
        </geometry>
      </collision>
    </link>
    <joint name="3" type="revolute">
      <origin xyz="0 0.135 0" rpy="0 0 0" />
      <parent link="2_Link" />
      <child link="3_Link" />
      <axis xyz="0 0 1" />
      <limit lower="-2.3562" upper="1.2217" effort="10.0" velocity="3.1416" />
    </joint>

    <link name="4_Link">
      <inertial>
        <origin xyz="0.0268017397762453 3.8050478860796E-06 -0.0386580641288729" rpy="0 0 0" />
        <mass value="5.4551423036358E-05" />
        <inertia ixx="6.19250472386076E-11" ixy="-6.6627251186149E-15" ixz="3.36952177502071E-14" iyy="4.37621105880679E-10" iyz="5.44000654518049E-15" izz="4.37369303303002E-10" />
      </inertial>
      <visual>
        <origin xyz="0 0 0" rpy="0 0 0" />
        <geometry>
          <mesh filename="4_Link.STL" />
        </geometry>
        <material name="">
          <color rgba="0.749019607843137 0.749019607843137 0.749019607843137 1" />
        </material>
      </visual>
      <collision>
        <origin xyz="0 0 0" rpy="0 0 0" />
        <geometry>
          <mesh filename="4_Link.STL" />
        </geometry>
      </collision>
    </link>
    <joint name="4" type="revolute">
      <origin xyz="0.0609985999996513 0.0380000639917407 0" rpy="0 -1.5707963267949 0" />
      <parent link="3_Link" />
      <child link="4_Link" />
      <axis xyz="0 0 1" />
      <limit lower="-2.9671" upper="2.9671" effort="10.0" velocity="5.2360" />
    </joint>

    <link name="5_Link">
      <inertial>
        <origin xyz="0.0205110139562634 2.54707156949197E-06 0.000506958591903185" rpy="0 0 0" />
        <mass value="0.16436203042711" />
        <inertia ixx="5.51456893060112E-05" ixy="8.28032699191258E-09" ixz="3.47996286604157E-06" iyy="0.000119500194381483" iyz="3.23812564504135E-09" izz="0.000115800437996737" />
      </inertial>
      <visual>
        <origin xyz="0 0 0" rpy="0 0 0" />
        <geometry>
          <mesh filename="5_Link.STL" />
        </geometry>
        <material name="">
          <color rgba="0.749019607843137 0.749019607843137 0.749019607843137 1" />
        </material>
      </visual>
      <collision>
        <origin xyz="0 0 0" rpy="0 0 0" />
        <geometry>
          <mesh filename="5_Link.STL" />
        </geometry>
      </collision>
    </link>
    <joint name="5" type="revolute">
      <origin xyz="0 0 -0.059" rpy="0 1.5707963267949 0" />
      <parent link="4_Link" />
      <child link="5_Link" />
      <axis xyz="0 0 1" />
      <limit lower="-2.0071" upper="2.0071" effort="10.0" velocity="5.2360" />
    </joint>

    <link name="6_Link">
      <inertial>
        <origin xyz="-4.93381640404023E-09 -3.06476243447373E-06 -0.0051537334161223" rpy="0 0 0" />
        <mass value="0.00318159115629491" />
        <inertia ixx="1.12761623790943E-07" ixy="1.20821854288624E-13" ixz="-7.10637835162442E-14" iyy="1.10034690670702E-07" iyz="-4.50963801973578E-11" izz="1.63299994669183E-07" />
      </inertial>
      <visual>
        <origin xyz="0 0 0" rpy="0 0 0" />
        <geometry>
          <mesh filename="6_Link.STL" />
        </geometry>
        <material name="">
          <color rgba="0.749019607843137 0.749019607843137 0.749019607843137 1" />
        </material>
      </visual>
      <collision>
        <origin xyz="0 0 0" rpy="0 0 0" />
        <geometry>
          <mesh filename="6_Link.STL" />
        </geometry>
      </collision>
    </link>
    <joint name="6" type="revolute">
      <origin xyz="0.059 0 0" rpy="0.0 -1.5707963267949 0" />
      <parent link="5_Link" />
      <child link="6_Link" />
      <axis xyz="0 0 1" />
      <limit lower="-6.2832" upper="6.2832" effort="10.0" velocity="8.7266" />
    </joint>
  </xacro:macro>
</robot>
